[2025-02-25T19:49:59.941+0000] {taskinstance.py:1957} INFO - Dependencies all met for dep_context=non-requeueable deps ti=<TaskInstance: load_bronze_accounts_created.bronze_accounts_created_task scheduled__2025-02-24T00:00:00+00:00 [queued]>
[2025-02-25T19:49:59.944+0000] {taskinstance.py:1957} INFO - Dependencies all met for dep_context=requeueable deps ti=<TaskInstance: load_bronze_accounts_created.bronze_accounts_created_task scheduled__2025-02-24T00:00:00+00:00 [queued]>
[2025-02-25T19:49:59.945+0000] {taskinstance.py:2171} INFO - Starting attempt 1 of 2
[2025-02-25T19:49:59.952+0000] {taskinstance.py:2192} INFO - Executing <Task(SimpleHttpOperator): bronze_accounts_created_task> on 2025-02-24 00:00:00+00:00
[2025-02-25T19:49:59.954+0000] {standard_task_runner.py:60} INFO - Started process 100 to run task
[2025-02-25T19:49:59.956+0000] {standard_task_runner.py:87} INFO - Running: ['***', 'tasks', 'run', 'load_bronze_accounts_created', 'bronze_accounts_created_task', 'scheduled__2025-02-24T00:00:00+00:00', '--job-id', '24', '--raw', '--subdir', 'DAGS_FOLDER/dynamic_api_trigger.py', '--cfg-path', '/tmp/tmpps2h_n69']
[2025-02-25T19:49:59.957+0000] {standard_task_runner.py:88} INFO - Job 24: Subtask bronze_accounts_created_task
[2025-02-25T19:49:59.979+0000] {task_command.py:423} INFO - Running <TaskInstance: load_bronze_accounts_created.bronze_accounts_created_task scheduled__2025-02-24T00:00:00+00:00 [running]> on host df64ebc03249
[2025-02-25T19:50:00.013+0000] {taskinstance.py:2481} INFO - Exporting env vars: AIRFLOW_CTX_DAG_OWNER='***' AIRFLOW_CTX_DAG_ID='load_bronze_accounts_created' AIRFLOW_CTX_TASK_ID='bronze_accounts_created_task' AIRFLOW_CTX_EXECUTION_DATE='2025-02-24T00:00:00+00:00' AIRFLOW_CTX_TRY_NUMBER='1' AIRFLOW_CTX_DAG_RUN_ID='scheduled__2025-02-24T00:00:00+00:00'
[2025-02-25T19:50:00.013+0000] {http.py:169} INFO - Calling HTTP method
[2025-02-25T19:50:00.020+0000] {taskinstance.py:2699} ERROR - Task failed with exception
Traceback (most recent call last):
  File "/home/airflow/.local/lib/python3.8/site-packages/airflow/models/taskinstance.py", line 433, in _execute_task
    result = execute_callable(context=context, **execute_callable_kwargs)
  File "/home/airflow/.local/lib/python3.8/site-packages/airflow/providers/http/operators/http.py", line 166, in execute
    return self.execute_sync(context=context)
  File "/home/airflow/.local/lib/python3.8/site-packages/airflow/providers/http/operators/http.py", line 170, in execute_sync
    response = self.hook.run(self.endpoint, self.data, self.headers, self.extra_options)
  File "/home/airflow/.local/lib/python3.8/site-packages/airflow/providers/http/operators/http.py", line 148, in hook
    conn = BaseHook.get_connection(conn_id)
  File "/home/airflow/.local/lib/python3.8/site-packages/airflow/hooks/base.py", line 82, in get_connection
    conn = Connection.get_connection_from_secrets(conn_id)
  File "/home/airflow/.local/lib/python3.8/site-packages/airflow/models/connection.py", line 479, in get_connection_from_secrets
    raise AirflowNotFoundException(f"The conn_id `{conn_id}` isn't defined")
airflow.exceptions.AirflowNotFoundException: The conn_id `api_service` isn't defined
[2025-02-25T19:50:00.022+0000] {taskinstance.py:1138} INFO - Marking task as UP_FOR_RETRY. dag_id=load_bronze_accounts_created, task_id=bronze_accounts_created_task, execution_date=20250224T000000, start_date=20250225T194959, end_date=20250225T195000
[2025-02-25T19:50:00.029+0000] {standard_task_runner.py:107} ERROR - Failed to execute job 24 for task bronze_accounts_created_task (The conn_id `api_service` isn't defined; 100)
[2025-02-25T19:50:00.064+0000] {local_task_job_runner.py:234} INFO - Task exited with return code 1
[2025-02-25T19:50:00.073+0000] {taskinstance.py:3281} INFO - 0 downstream tasks scheduled from follow-on schedule check
