[2025-02-26T15:02:44.936+0000] {taskinstance.py:1957} INFO - Dependencies all met for dep_context=non-requeueable deps ti=<TaskInstance: load_bronze_accounts_deleted.bronze_accounts_deleted_trigger scheduled__2025-02-25T00:00:00+00:00 [queued]>
[2025-02-26T15:02:44.940+0000] {taskinstance.py:1957} INFO - Dependencies all met for dep_context=requeueable deps ti=<TaskInstance: load_bronze_accounts_deleted.bronze_accounts_deleted_trigger scheduled__2025-02-25T00:00:00+00:00 [queued]>
[2025-02-26T15:02:44.940+0000] {taskinstance.py:2171} INFO - Starting attempt 10 of 11
[2025-02-26T15:02:44.947+0000] {taskinstance.py:2192} INFO - Executing <Task(SimpleHttpOperator): bronze_accounts_deleted_trigger> on 2025-02-25 00:00:00+00:00
[2025-02-26T15:02:44.949+0000] {standard_task_runner.py:60} INFO - Started process 203 to run task
[2025-02-26T15:02:44.951+0000] {standard_task_runner.py:87} INFO - Running: ['***', 'tasks', 'run', 'load_bronze_accounts_deleted', 'bronze_accounts_deleted_trigger', 'scheduled__2025-02-25T00:00:00+00:00', '--job-id', '45', '--raw', '--subdir', 'DAGS_FOLDER/dynamic_api_trigger.py', '--cfg-path', '/tmp/tmpt2w0avf0']
[2025-02-26T15:02:44.952+0000] {standard_task_runner.py:88} INFO - Job 45: Subtask bronze_accounts_deleted_trigger
[2025-02-26T15:02:44.976+0000] {task_command.py:423} INFO - Running <TaskInstance: load_bronze_accounts_deleted.bronze_accounts_deleted_trigger scheduled__2025-02-25T00:00:00+00:00 [running]> on host 6746a23eb18f
[2025-02-26T15:02:45.008+0000] {taskinstance.py:2481} INFO - Exporting env vars: AIRFLOW_CTX_DAG_OWNER='***' AIRFLOW_CTX_DAG_ID='load_bronze_accounts_deleted' AIRFLOW_CTX_TASK_ID='bronze_accounts_deleted_trigger' AIRFLOW_CTX_EXECUTION_DATE='2025-02-25T00:00:00+00:00' AIRFLOW_CTX_TRY_NUMBER='10' AIRFLOW_CTX_DAG_RUN_ID='scheduled__2025-02-25T00:00:00+00:00'
[2025-02-26T15:02:45.009+0000] {http.py:169} INFO - Calling HTTP method
[2025-02-26T15:02:45.012+0000] {base.py:83} INFO - Using connection ID 'api_service' for task execution.
[2025-02-26T15:02:45.015+0000] {base.py:83} INFO - Using connection ID 'api_service' for task execution.
[2025-02-26T15:02:45.017+0000] {http.py:221} WARNING - HTTPConnectionPool(host='localhost', port=8000): Max retries exceeded with url: /http://localhost:8000/bronze/accounts_deleted/execute (Caused by NewConnectionError('<urllib3.connection.HTTPConnection object at 0xffff7dab29d0>: Failed to establish a new connection: [Errno 111] Connection refused')) Tenacity will retry to execute the operation
[2025-02-26T15:02:45.018+0000] {taskinstance.py:2699} ERROR - Task failed with exception
Traceback (most recent call last):
  File "/home/airflow/.local/lib/python3.8/site-packages/urllib3/connection.py", line 174, in _new_conn
    conn = connection.create_connection(
  File "/home/airflow/.local/lib/python3.8/site-packages/urllib3/util/connection.py", line 95, in create_connection
    raise err
  File "/home/airflow/.local/lib/python3.8/site-packages/urllib3/util/connection.py", line 85, in create_connection
    sock.connect(sa)
ConnectionRefusedError: [Errno 111] Connection refused

During handling of the above exception, another exception occurred:

Traceback (most recent call last):
  File "/home/airflow/.local/lib/python3.8/site-packages/urllib3/connectionpool.py", line 715, in urlopen
    httplib_response = self._make_request(
  File "/home/airflow/.local/lib/python3.8/site-packages/urllib3/connectionpool.py", line 416, in _make_request
    conn.request(method, url, **httplib_request_kw)
  File "/home/airflow/.local/lib/python3.8/site-packages/urllib3/connection.py", line 244, in request
    super(HTTPConnection, self).request(method, url, body=body, headers=headers)
  File "/usr/local/lib/python3.8/http/client.py", line 1256, in request
    self._send_request(method, url, body, headers, encode_chunked)
  File "/usr/local/lib/python3.8/http/client.py", line 1302, in _send_request
    self.endheaders(body, encode_chunked=encode_chunked)
  File "/usr/local/lib/python3.8/http/client.py", line 1251, in endheaders
    self._send_output(message_body, encode_chunked=encode_chunked)
  File "/usr/local/lib/python3.8/http/client.py", line 1011, in _send_output
    self.send(msg)
  File "/usr/local/lib/python3.8/http/client.py", line 951, in send
    self.connect()
  File "/home/airflow/.local/lib/python3.8/site-packages/urllib3/connection.py", line 205, in connect
    conn = self._new_conn()
  File "/home/airflow/.local/lib/python3.8/site-packages/urllib3/connection.py", line 186, in _new_conn
    raise NewConnectionError(
urllib3.exceptions.NewConnectionError: <urllib3.connection.HTTPConnection object at 0xffff7dab29d0>: Failed to establish a new connection: [Errno 111] Connection refused

During handling of the above exception, another exception occurred:

Traceback (most recent call last):
  File "/home/airflow/.local/lib/python3.8/site-packages/requests/adapters.py", line 486, in send
    resp = conn.urlopen(
  File "/home/airflow/.local/lib/python3.8/site-packages/urllib3/connectionpool.py", line 799, in urlopen
    retries = retries.increment(
  File "/home/airflow/.local/lib/python3.8/site-packages/urllib3/util/retry.py", line 592, in increment
    raise MaxRetryError(_pool, url, error or ResponseError(cause))
urllib3.exceptions.MaxRetryError: HTTPConnectionPool(host='localhost', port=8000): Max retries exceeded with url: /http://localhost:8000/bronze/accounts_deleted/execute (Caused by NewConnectionError('<urllib3.connection.HTTPConnection object at 0xffff7dab29d0>: Failed to establish a new connection: [Errno 111] Connection refused'))

During handling of the above exception, another exception occurred:

Traceback (most recent call last):
  File "/home/airflow/.local/lib/python3.8/site-packages/airflow/models/taskinstance.py", line 433, in _execute_task
    result = execute_callable(context=context, **execute_callable_kwargs)
  File "/home/airflow/.local/lib/python3.8/site-packages/airflow/providers/http/operators/http.py", line 166, in execute
    return self.execute_sync(context=context)
  File "/home/airflow/.local/lib/python3.8/site-packages/airflow/providers/http/operators/http.py", line 170, in execute_sync
    response = self.hook.run(self.endpoint, self.data, self.headers, self.extra_options)
  File "/home/airflow/.local/lib/python3.8/site-packages/airflow/providers/http/hooks/http.py", line 166, in run
    return self.run_and_check(session, prepped_request, extra_options)
  File "/home/airflow/.local/lib/python3.8/site-packages/airflow/providers/http/hooks/http.py", line 222, in run_and_check
    raise ex
  File "/home/airflow/.local/lib/python3.8/site-packages/airflow/providers/http/hooks/http.py", line 214, in run_and_check
    response = session.send(prepped_request, **send_kwargs)
  File "/home/airflow/.local/lib/python3.8/site-packages/requests/sessions.py", line 703, in send
    r = adapter.send(request, **kwargs)
  File "/home/airflow/.local/lib/python3.8/site-packages/requests/adapters.py", line 519, in send
    raise ConnectionError(e, request=request)
requests.exceptions.ConnectionError: HTTPConnectionPool(host='localhost', port=8000): Max retries exceeded with url: /http://localhost:8000/bronze/accounts_deleted/execute (Caused by NewConnectionError('<urllib3.connection.HTTPConnection object at 0xffff7dab29d0>: Failed to establish a new connection: [Errno 111] Connection refused'))
[2025-02-26T15:02:45.022+0000] {taskinstance.py:1138} INFO - Marking task as UP_FOR_RETRY. dag_id=load_bronze_accounts_deleted, task_id=bronze_accounts_deleted_trigger, execution_date=20250225T000000, start_date=20250226T150244, end_date=20250226T150245
[2025-02-26T15:02:45.029+0000] {standard_task_runner.py:107} ERROR - Failed to execute job 45 for task bronze_accounts_deleted_trigger (HTTPConnectionPool(host='localhost', port=8000): Max retries exceeded with url: /http://localhost:8000/bronze/accounts_deleted/execute (Caused by NewConnectionError('<urllib3.connection.HTTPConnection object at 0xffff7dab29d0>: Failed to establish a new connection: [Errno 111] Connection refused')); 203)
[2025-02-26T15:02:45.051+0000] {local_task_job_runner.py:234} INFO - Task exited with return code 1
[2025-02-26T15:02:45.059+0000] {taskinstance.py:3281} INFO - 0 downstream tasks scheduled from follow-on schedule check
